Workbook

Sheet Tipos de Dato
A1: Tipos de Datos - Tabla Comparativa
A2: # | B2: Tipo de Dato Genérico | C2: Descripción | D2: En PosgreSQL | E2: En MySQL | F2: En MS SQL Server
D3: Versión: | E3: Versión: | F3: Versión:
A4: 1 | B4: AUTOINCREMENTABLE | C4: Genera valores numéricos automáticos para identificadores únicos | D4: SERIAL | E4: INT AUTO_INCREMENT | F4: INT IDENTITY(1,1)
A5: =A4+1 -> 2 | B5: UUID | C5: Identificador único universal | D5: UUID | E5: CHAR(36) | F5: UNIQUEIDENTIFIER
A6: =A5+1 -> 3 | B6: ENTERO | C6: Almacena números enteros | D6: INTEGER | E6: INT | F6: INT
A7: =A6+1 -> 4 | B7: DECIMAL | C7: Almacena números con decimales | D7: DECIMAL(p,s) | E7: DECIMAL(p,s) | F7: DECIMAL(p,s)
A8: =A7+1 -> 5 | B8: LÓGICO | C8: Valores verdadero o falso | D8: BOOLEAN | E8: BOOLEAN | F8: BIT
A9: =A8+1 -> 6 | B9: TEXTO | C9: Almacena texto largo | D9: TEXT | E9: TEXT | F9: TEXT
A10: =A9+1 -> 7 | B10: CARACTER | C10: Almacena caracteres de longitud fija | D10: CHAR(n) | E10: CHAR(n) | F10: CHAR(n)
A11: =A10+1 -> 8 | B11: FECHA | C11: Almacena fechas | D11: DATE | E11: DATE | F11: DATE
A12: =A11+1 -> 9 | B12: FECHA_HORA | C12: Almacena fecha y hora | D12: TIMESTAMP | E12: TIMESTAMP | F12: DATETIME
A13: =A12+1 -> 10 | B13: HORA | C13: Almacena solo la hora | D13: TIME | E13: TIME | F13: TIME
A14: =A13+1 -> 11 | B14: URL | C14: Almacena enlaces web | D14: VARCHAR(255) | E14: VARCHAR(255) | F14: VARCHAR(255)
A15: =A14+1 -> 12 | B15: ENUM | C15: Lista limitada de valores | D15: ENUM | E15: ENUM | F15: VARCHAR + CHECK
A16: =A15+1 -> 13 | B16: TEXTO_CORTO | C16: Texto de longitud reducida | D16: VARCHAR(n) | E16: VARCHAR(n) | F16: VARCHAR(n)
... A21: =A20+1 -> 18 | B21: AUDIO | C21: Almacena archivos de audio | D21: BYTEA | E21: BLOB | F21: VARBINARY(MAX)

Sheet Invetario de Tablas
A1: Modelo Lógico - Tablas resultantes del Diccionario Genérico (corregido)
A2: INVENTARIO DE TABLAS Este inventario es el mismo para los 3 SGBDs: PostgreSQL, MySQL y MS SQL Server. Todos los diccionarios deben tomar la misma cantidad y los mismos nombres de esta tablas
A3: # | B3: Tabla | C3: Descripción Tabla | D3: Observaciones
A4: 1 | B4: usuario | C4: Almacena la información principal de los usuarios registrados en la red social | D4: Tabla independiente principal del sistema
A5: =A4+1 -> 2 | B5: grupo | C5: Guarda los grupos creados por los usuarios para estudio, actividades o intereses | D5: Relacionada con usuario
A6: =A5+1 -> 3 | B6: perfil | C6: Contiene información adicional del perfil de cada usuario | D6: Relación uno a uno con usuario
A7: =A6+1 -> 4 | B7: publicacion | C7: Registra las publicaciones realizadas por los usuarios | D7: Relacionada con usuario
A8: =A7+1 -> 5 | B8: evento | C8: Almacena los eventos creados dentro de los grupos | D8: Relacionada con grupo
A9: =A8+1 -> 6 | B9: comentario | C9: Guarda los comentarios realizados en publicaciones | D9: Relacionada con usuario y publicacion
A10: =A9+1 -> 7 | B10: reaccion | C10: Registra las reacciones de los usuarios a las publicaciones | D10: Relacionada con usuario y publicacion
A11: =A10+1 -> 8 | B11: mensaje | C11: Gestiona los mensajes privados entre usuarios | D11: Relación usuario ↔ usuario
A12: =A11+1 -> 9 | B12: solicitud_amistad | C12: Almacena las solicitudes de amistad entre usuarios | D12: Relación usuario ↔ usuario
A13: =A12+1 -> 10 | B13: reporte | C13: Guarda los reportes realizados sobre publicaciones | D13: Relacionada con usuario y publicacion
A14: =A13+1 -> 11 | B14: notificacion | C14: Almacena las notificaciones enviadas a los usuarios | D14: Relacionada con usuario
A15: =A14+1 -> 12
A16: =A15+1 -> 13
A17: =A16+1 -> 14
A18: =A17+1 -> 15
A19: =A18+1 -> 16
A20: =A19+1 -> 17
A21: =A20+1 -> 18
A22: =A21+1 -> 19
A23: =A22+1 -> 20
A24: =A23+1 -> 21
A25: =A24+1 -> 22
A26: =A25+1 -> 23
... A28: =A27+1 -> 25

Sheet Diccionario Datos - PostgreSQL
A1: PostgreSQL - Tablas en Detalle
A3: ='Invetario de Tablas'!A4 -> 1 | B3: Tabla | C3: usuario | G3: Descripción Tabla | K3: Usuarios registrados en la red social | X3: Versión | Y3: 1
A4: # | B4: Campo | C4: Descripción Campo | G4: Tipo Dato - PostgreSQL | K4: Tamaño | O4: Nulo | R4: PK | T4: FK | V4: UK | X4: Nota/Comentarios
A5: 1 | B5: id_usuario | C5: Identificador único del usuario | G5: SERIAL | O5: N | R5: S | X5: Clave primaria autoincrementable
A6: 2 | B6: nombre | C6: Nombre completo del usuario | G6: VARCHAR | K6: 120 | O6: N | X6: Información básica del usuario
A7: 3 | B7: correo | C7: Correo electrónico del usuario | G7: VARCHAR | K7: 120 | O7: N | V7: S | X7: Debe ser único
A8: 4 | B8: contraseña | C8: Contraseña de acceso | G8: VARCHAR | K8: 120 | O8: N | X8: Almacena contraseña cifrada
A9: 5 | B9: tipo_usuario | C9: Tipo de usuario registrado | G9: VARCHAR | K9: 50 | O9: N | X9: estudiante, docente, empleado, etc
A10: 6 | B10: fecha_registro | C10: Fecha de creación de la cuenta | G10: DATE | O10: N | X10: Registro automático
A11: 7 | B11: perfil_usuario | C11: Información semi-estructurada del usuario | G11: JSONB | O11: S | X11: Datos Big Data / NoSQL
A16: ='Invetario de Tablas'!A5 -> 2 | B16: Tabla | C16: grupo | G16: Descripción Tabla | K16: Grupos creados por usuarios | X16: Versión | Y16: 2
A17: # | B17: Campo | C17: Descripción Campo | G17: Tipo Dato - PostgreSQL | K17: Tamaño | O17: Nulo | R17: PK | T17: FK | V17: UK | X17: Nota/Comentarios
A18: 1 | B18: id_grupo | C18: Identificador único del grupo | G18: SERIAL | O18: N | R18: S | X18: Clave primaria
A19: 2 | B19: nombre_grupo | C19: Nombre del grupo | G19: VARCHAR | K19: 120 | O19: N | X19: Nombre visible
A20: 3 | B20: descripcion | C20: Descripción del grupo | G20: TEXT | O20: S | X20: Información general
A21: 4 | B21: fecha_creacion | C21: Fecha de creación del grupo | G21: DATE | O21: S | X21: Registro automático
A22: 5 | B22: id_usuario | C22: Usuario creador del grupo | G22: INTEGER | O22: N | T22: S | X22: Relación con usuario
A24: N
A28: 3 | B28: Tabla | C28: perfil | G28: Descripción Tabla | K28: Información adicional del perfil | X28: Versión | Y28: 3
A29: # | B29: Campo | C29: Descripción Campo | G29: Tipo Dato - PostgreSQL | K29: Tamaño | O29: Nulo | R29: PK | T29: FK | V29: UK | X29: Nota/Comentarios
A30: 1 | B30: id_perfil | C30: Identificador del perfil | G30: SERIAL | O30: N | R30: S | X30: Clave primaria
A31: 2 | B31: id_usuario | C31: Usuario asociado al perfil | G31: INTEGER | O31: N | T31: S | V31: S | X31: Relación uno a uno
A32: 3 | B32: biografia | C32: Descripción personal | G32: TEXT | O32: S | X32: Información libre
A33: 4 | B33: intereses | C33: Gustos o intereses | G33: TEXT | O33: S | X33: Información personal
A34: 5 | B34: habilidades | C34: Habilidades del usuario | G34: TEXT | O34: S | X34: Aptitudes o conocimientos
A39: 4 | B39: Tabla | C39: publicacion | G39: Descripción Tabla | X39: Versión | Y39: 4
A40: # | B40: Campo | C40: Descripción Campo | G40: Tipo Dato - PostgreSQL | K40: Tamaño | O40: Nulo | R40: PK | T40: FK | V40: UK | X40: Nota/Comentarios
A41: 1 | B41: id_publicacion | C41: Identificador de la publicación | G41: SERIAL | O41: N | R41: S | X41: Clave primaria
A42: 2 | B42: id_usuario | C42: Usuario que publica | G42: INTEGER | O42: N | T42: S | X42: Relación con usuario
A43: 3 | B43: contenido | C43: Texto de la publicación | G43: TEXT | O43: N | X43: Contenido principal
A44: 4 | B44: fecha_publicacion | C44: Fecha de publicación | G44: DATE | O44: N | X44: Registro automático
A45: 5 | B45: visibilidad | C45: Nivel de visibilidad | G45: VARCHAR | K45: 20 | O45: S | X45: pública, privada o amigos
A46: 6 | B46: datos_multimedia | C46: Información multimedia | G46: JSONB | O46: S | X46: Datos semi-estructurados
A53: 5 | B53: Tabla | C53: evento | G53: Descripción Tabla | K53: Eventos creados dentro de grupos | X53: Versión | Y53: 5
A54: # | B54: Campo | C54: Descripción Campo | G54: Tipo Dato - PostgreSQL | K54: Tamaño | O54: Nulo | R54: PK | T54: FK | V54: UK | X54: Nota/Comentarios
A55: 1 | B55: id_evento | C55: Identificador del evento | G55: SERIAL | O55: N | R55: S | X55: Clave primaria
A56: 2 | B56: nombre_evento | C56: Nombre del evento | G56: VARCHAR | K56: 120 | O56: N | X56: Nombre visible
A57: 3 | B57: descripcion | C57: Descripción del evento | G57: TEXT | O57: S | X57: Información del evento
A58: 4 | B58: fecha_evento | C58: Fecha programada del evento | G58: DATE | O58: N | X58: Fecha principal
A59: 5 | B59: lugar | C59: Lugar del evento | G59: VARCHAR | K59: 120 | O59: S | X59: Ubicación física o virtual
...

Sheet Diccionario Datos - MySQL
A1: MySQL - Tablas en Detalle
A3: ='Invetario de Tablas'!A4 -> 1 | B3: Tabla | C3: usuario | G3: Descripción Tabla | K3: Usuarios registrados en la red social | X3: Versión | Y3: 1
A4: # | B4: Campo | C4: Descripción Campo | G4: Tipo Dato - MySQL | K4: Tamaño | O4: Nulo | R4: PK | T4: FK | V4: UK | X4: Nota/Comentarios
A5: 1 | B5: id_usuario | C5: Identificador único del usuario | G5: INT AUTO_INCREMENT | O5: N | R5: S | X5: Clave primaria autoincrementable
A6: 2 | B6: nombre | C6: Nombre completo del usuario | G6: VARCHAR | K6: 120 | O6: N | X6: Información básica
A7: 3 | B7: correo | C7: Correo electrónico del usuario | G7: VARCHAR | K7: 120 | O7: N | V7: S | X7: Debe ser único
A8: 4 | B8: contraseña | C8: Contraseña de acceso | G8: VARCHAR | K8: 120 | O8: N | X8: Contraseña cifrada
A9: 5 | B9: tipo_usuario | C9: Tipo de usuario registrado | G9: VARCHAR | K9: 50 | O9: N | X9: estudiante, docente, etc
A10: 6 | B10: fecha_registro | C10: Fecha de creación de la cuenta | G10: DATE | O10: N | X10: Registro automático
A11: 7 | B11: perfil_usuario | C11: Información semi-estructurada del usuario | G11: JSON | O11: S | X11: Datos Big Data / NoSQL
A14: ='Invetario de Tablas'!A5 -> 2 | B14: Tabla | C14: grupo | G14: Descripción Tabla | K14: Grupos creados por usuarios | X14: Versión | Y14: 2
A15: # | B15: Campo | C15: Descripción Campo | G15: Tipo Dato - MySQL | K15: Tamaño | O15: Nulo | R15: PK | T15: FK | V15: UK | X15: Nota/Comentarios
A16: 1 | B16: id_grupo | C16: Identificador único del grupo | G16: INT AUTO_INCREMENT | O16: N | R16: S | X16: Clave primaria
A17: 2 | B17: nombre_grupo | C17: Nombre del grupo | G17: VARCHAR | K17: 120 | O17: N | X17: Nombre visible
A18: 3 | B18: descripcion | C18: Descripción del grupo | G18: TEXT | O18: S | X18: Información general
A19: 4 | B19: fecha_creacion | C19: Fecha de creación del grupo | G19: DATE | O19: S | X19: Registro automático
A20: 5 | B20: id_usuario | C20: Usuario creador del grupo | G20: INT | O20: N | T20: S | X20: Relación con usuario
A25: 3 | B25: Tabla | C25: perfil | G25: Descripción Tabla | K25: Información adicional del perfil | X25: Versión | Y25: 3
A26: # | B26: Campo | C26: Descripción Campo | G26: Tipo Dato - MySQL | K26: Tamaño | O26: Nulo | R26: PK | T26: FK | V26: UK | X26: Nota/Comentarios
A27: 1 | B27: id_perfil | C27: Identificador del perfil | G27: INT AUTO_INCREMENT | O27: N | R27: S | X27: Clave primaria
A28: 2 | B28: id_usuario | C28: Usuario asociado al perfil | G28: INT | O28: N | T28: S | V28: S | X28: Relación uno a uno
A29: 3 | B29: biografia | C29: Descripción personal | G29: TEXT | O29: S | X29: Información libre
A30: 4 | B30: intereses | C30: Gustos o intereses | G30: TEXT | O30: S | X30: Información personal
A31: 5 | B31: habilidades | C31: Habilidades del usuario | G31: TEXT | O31: S | X31: Aptitudes o conocimientos
A37: 4 | B37: Tabla | C37: publicacion | G37: Descripción Tabla | K37: Publicaciones realizadas por usuarios | X37: Versión | Y37: 4
A38: # | B38: Campo | C38: Descripción Campo | G38: Tipo Dato - MySQL | K38: Tamaño | O38: Nulo | R38: PK | T38: FK | V38: UK | X38: Nota/Comentarios
A39: 1 | B39: id_publicacion | C39: Identificador de la publicación | G39: INT AUTO_INCREMENT | O39: N | R39: S | X39: Clave primaria
A40: 2 | B40: id_usuario | C40: Usuario que publica | G40: INT | O40: N | T40: S | X40: Relación con usuario
A41: 3 | B41: contenido | C41: Texto de la publicación | G41: TEXT | O41: N | X41: Contenido principal
A42: 4 | B42: fecha_publicacion | C42: Fecha de publicación | G42: DATE | O42: N | X42: Registro automático
A43: 5 | B43: visibilidad | C43: Nivel de visibilidad | G43: VARCHAR | K43: 20 | O43: S | X43: pública, privada o amigos
A44: 6 | B44: datos_multimedia | C44: Información multimedia | G44: JSON | O44: S | X44: Datos semi-estructurados
A50: 5 | B50: Tabla | C50: evento | G50: Descripción Tabla | K50: Eventos creados dentro de grupos | X50: Versión | Y50: 5
A51: # | B51: Campo | C51: Descripción Campo | G51: Tipo Dato - MySQL | K51: Tamaño | O51: Nulo | R51: PK | T51: FK | V51: UK | X51: Nota/Comentarios
A52: 1 | B52: id_evento | C52: Identificador del evento | G52: INT AUTO_INCREMENT | O52: N | R52: S | X52: Clave primaria
A53: 2 | B53: nombre_evento | C53: Nombre del evento | G53: VARCHAR | K53: 120 | O53: N | X53: Nombre visible
A54: 3 | B54: descripcion | C54: Descripción del evento | G54: TEXT | O54: S | X54: Información del evento
A55: 4 | B55: fecha_evento | C55: Fecha programada del evento | G55: DATE | O55: N | X55: Fecha principal
A56: 5 | B56: lugar | C56: Lugar del evento | G56: VARCHAR | O56: S | X56: Ubicación física o virtual
A57: 6 | B57: id_grupo | C57: Grupo asociado al evento | G57: INT | O57: N | T57: S | X57: Relación con grupo
...

Sheet Diccionario Datos - MS SQL Serv
A1: MS SQL Server - Tablas en Detalle
A3: ='Invetario de Tablas'!A4 -> 1 | B3: Tabla | C3: usuario | G3: Descripción Tabla | K3: Usuarios registrados en la red social | X3: Versión | Y3: 1
A4: # | B4: Campo | C4: Descripción Campo | G4: Tipo Dato - MS SQL Server | K4: Tamaño | O4: Nulo | R4: PK | T4: FK | V4: UK | X4: Nota/Comentarios
A5: 1 | B5: id_usuario | C5: Identificador único del usuario | G5: INT IDENTITY(1,1) | O5: N | R5: S | X5: Clave primaria autoincrementable
A6: 2 | B6: nombre | C6: Nombre completo del usuario | G6: VARCHAR | K6: 120 | O6: N | X6: Información básica
A7: 3 | B7: correo | C7: Correo electrónico del usuario | G7: VARCHAR | K7: 120 | O7: N | V7: S | X7: Debe ser único
A8: 4 | B8: contraseña | C8: Contraseña de acceso | G8: VARCHAR | K8: 120 | O8: N | X8: Contraseña cifrada
A9: 5 | B9: tipo_usuario | C9: Tipo de usuario registrado | G9: VARCHAR | K9: 50 | O9: N | X9: estudiante, docente, etc
A10: 6 | B10: fecha_registro | C10: Fecha de creación de la cuenta | G10: DATE | O10: N | X10: Registro automático
A11: 7 | B11: perfil_usuario | C11: Información semi-estructurada del usuario | G11: NVARCHAR(MAX) | K11: MAX | O11: S | X11: Datos Big Data / NoSQL
A16: ='Invetario de Tablas'!A5 -> 2 | B16: Tabla | C16: grupo | G16: Descripción Tabla | K16: Grupos creados por usuarios | X16: Versión | Y16: 2
A17: # | B17: Campo | C17: Descripción Campo | G17: Tipo Dato - MS SQL Server | K17: Tamaño | O17: Nulo | R17: PK | T17: FK | V17: UK | X17: Nota/Comentarios
A18: 1 | B18: id_grupo | C18: Identificador único del grupo | G18: INT IDENTITY(1,1) | O18: N | R18: S | X18: Clave primaria
A19: 2 | B19: nombre_grupo | C19: Nombre del grupo | G19: VARCHAR | K19: 120 | O19: N | X19: Nombre visible
A20: 3 | B20: descripcion | C20: Descripción del grupo | G20: TEXT | O20: S | X20: Información general
A21: 4 | B21: fecha_creacion | C21: Fecha de creación del grupo | G21: DATE | O21: S | X21: Registro automático
A22: 5 | B22: id_usuario | C22: Usuario creador del grupo | G22: INT | O22: N | T22: S | X22: Relación con usuario
A28: 3 | B28: Tabla | C28: perfil | G28: Descripción Tabla | K28: Información adicional del perfil | X28: Versión | Y28: 3
A29: # | B29: Campo | C29: Descripción Campo | G29: Tipo Dato - MS SQL Server | K29: Tamaño | O29: Nulo | R29: PK | T29: FK | V29: UK | X29: Nota/Comentarios
A30: 1 | B30: id_perfil | C30: Identificador del perfil | G30: INT IDENTITY(1,1) | O30: N | R30: S | X30: Clave primaria
A31: 2 | B31: id_usuario | C31: Usuario asociado al perfil | G31: INT | O31: N | T31: S | V31: S | X31: Relación uno a uno
A32: 3 | B32: biografia | C32: Descripción personal | G32: TEXT | O32: S | X32: Información libre
A33: 4 | B33: intereses | C33: Gustos o intereses | G33: TEXT | O33: S | X33: Información personal
A34: 5 | B34: habilidades | C34: Habilidades del usuario | G34: TEXT | O34: S | X34: Aptitudes o conocimientos
A41: 4 | B41: Tabla | C41: publicacion | G41: Descripción Tabla | K41: Publicaciones realizadas por usuarios | X41: Versión | Y41: 4
A42: # | B42: Campo | C42: Descripción Campo | G42: Tipo Dato - MS SQL Server | K42: Tamaño | O42: Nulo | R42: PK | T42: FK | V42: UK | X42: Nota/Comentarios
A43: 1 | B43: id_publicacion | C43: Identificador de la publicación | G43: INT IDENTITY(1,1) | O43: N | R43: S | X43: Clave primaria
A44: 2 | B44: id_usuario | C44: Usuario que publica | G44: INT | O44: N | T44: S | X44: Relación con usuario
A45: 3 | B45: contenido | C45: Texto de la publicación | G45: TEXT | O45: N | X45: Contenido principal
A46: 4 | B46: fecha_publicacion | C46: Fecha de publicación | G46: DATE | O46: N | X46: Registro automático
A47: 5 | B47: visibilidad | C47: Nivel de visibilidad | G47: VARCHAR | K47: 20 | O47: S | X47: pública, privada o amigos
A48: 6 | B48: datos_multimedia | C48: Información multimedia | G48: NVARCHAR(MAX) | K48: MAX | O48: S | X48: Datos semi-estructurados
A54: 5 | B54: Tabla | C54: evento | G54: Descripción Tabla | K54: Eventos creados dentro de grupos | X54: Versión | Y54: 5
A55: # | B55: Campo | C55: Descripción Campo | G55: Tipo Dato - MS SQL Server | K55: Tamaño | O55: Nulo | R55: PK | T55: FK | V55: UK | X55: Nota/Comentarios
A56: 1 | B56: id_evento | C56: Identificador del evento | G56: INT IDENTITY(1,1) | O56: N | R56: S | X56: Clave primaria
A57: 2 | B57: nombre_evento | C57: Nombre del evento | G57: VARCHAR | K57: 120 | O57: N | X57: Nombre visible
A58: 3 | B58: descripcion | C58: Descripción del evento | G58: TEXT | O58: S | X58: Información del evento
A59: 4 | B59: fecha_evento | C59: Fecha programada del evento | G59: DATE | O59: N | X59: Fecha principal
A60: 5 | B60: lugar | C60: Lugar del evento | G60: VARCHAR | K60: 120 | O60: S | X60: Ubicación física o virtual
A61: 6 | B61: id_grupo | C61: Grupo asociado al evento | G61: INT | O61: N | T61: S | X61: Relación con grupo
...
